2023-09-21 14:26:31,409 INFO    MainThread:8384 [wandb_setup.py:_flush():76] Configure stats pid to 8384
2023-09-21 14:26:31,409 INFO    MainThread:8384 [wandb_setup.py:_flush():76] Loading settings from C:\Users\PC\.config\wandb\settings
2023-09-21 14:26:31,409 INFO    MainThread:8384 [wandb_setup.py:_flush():76] Loading settings from D:\Howsam\Deep Catalyst\project 1 language modeling\code\howsam\wandb\settings
2023-09-21 14:26:31,409 INFO    MainThread:8384 [wandb_setup.py:_flush():76] Loading settings from environment variables: {'_require_service': 'True'}
2023-09-21 14:26:31,409 INFO    MainThread:8384 [wandb_setup.py:_flush():76] Inferring run settings from compute environment: {'program_relpath': 'main.py', 'program': 'D:/Howsam/Deep Catalyst/project 1 language modeling/code/howsam/main.py'}
2023-09-21 14:26:31,409 INFO    MainThread:8384 [wandb_setup.py:_flush():76] Applying login settings: {'api_key': '***REDACTED***'}
2023-09-21 14:26:31,409 INFO    MainThread:8384 [wandb_setup.py:_flush():76] Applying login settings: {'api_key': '***REDACTED***'}
2023-09-21 14:26:31,409 INFO    MainThread:8384 [wandb_init.py:_log_setup():461] Logging user logs to D:\Howsam\Deep Catalyst\project 1 language modeling\code\howsam\wandb\run-20230921_142631-2lnld8mq\logs\debug.log
2023-09-21 14:26:31,409 INFO    MainThread:8384 [wandb_init.py:_log_setup():462] Logging internal logs to D:\Howsam\Deep Catalyst\project 1 language modeling\code\howsam\wandb\run-20230921_142631-2lnld8mq\logs\debug-internal.log
2023-09-21 14:26:31,409 INFO    MainThread:8384 [wandb_init.py:init():495] calling init triggers
2023-09-21 14:26:31,409 INFO    MainThread:8384 [wandb_init.py:init():498] wandb.init called with sweep_config: {}
config: {'learning_rate': 0.5, 'epochs': 31}
2023-09-21 14:26:31,409 INFO    MainThread:8384 [wandb_init.py:init():548] starting backend
2023-09-21 14:26:31,409 INFO    MainThread:8384 [wandb_init.py:init():552] setting up manager
2023-09-21 14:26:31,424 INFO    MainThread:8384 [backend.py:_multiprocessing_setup():97] multiprocessing start_methods=spawn, using: spawn
2023-09-21 14:26:31,424 INFO    MainThread:8384 [wandb_init.py:init():558] backend started and connected
2023-09-21 14:26:31,424 INFO    MainThread:8384 [wandb_init.py:init():636] updated telemetry
2023-09-21 14:26:31,440 INFO    MainThread:8384 [wandb_init.py:init():667] communicating run to backend with 30 second timeout
2023-09-21 14:26:34,598 WARNING MsgRouterThr:8384 [router.py:message_loop():76] message_loop has been closed
2023-09-21 14:27:01,456 INFO    MainThread:8384 [interface_shared.py:_communicate_run():331] couldn't get run from backend
2023-09-21 14:27:01,456 ERROR   MainThread:8384 [wandb_init.py:init():676] backend process timed out
2023-09-21 14:27:01,456 ERROR   MainThread:8384 [wandb_init.py:init():685] encountered error: Error communicating with wandb process
For more info see: https://docs.wandb.ai/library/init#init-start-error
2023-09-21 14:28:06,114 INFO    MainThread:8384 [wandb_settings.py:_apply_login():1531] Applying login settings: {'api_key': '***REDACTED***'}
2023-09-21 14:28:06,114 INFO    MainThread:8384 [wandb_settings.py:_apply_login():1531] Applying login settings: {'api_key': '***REDACTED***'}
2023-09-21 14:28:09,361 ERROR   Thread-75 :8384 [retry.py:__call__():154] Retry attempt failed:
Traceback (most recent call last):
  File "C:\Users\PC\anaconda3\envs\howsam-deep\lib\site-packages\urllib3\connectionpool.py", line 700, in urlopen
    self._prepare_proxy(conn)
  File "C:\Users\PC\anaconda3\envs\howsam-deep\lib\site-packages\urllib3\connectionpool.py", line 996, in _prepare_proxy
    conn.connect()
  File "C:\Users\PC\anaconda3\envs\howsam-deep\lib\site-packages\urllib3\connection.py", line 364, in connect
    self.sock = conn = self._connect_tls_proxy(hostname, conn)
  File "C:\Users\PC\anaconda3\envs\howsam-deep\lib\site-packages\urllib3\connection.py", line 499, in _connect_tls_proxy
    socket = ssl_wrap_socket(
  File "C:\Users\PC\anaconda3\envs\howsam-deep\lib\site-packages\urllib3\util\ssl_.py", line 453, in ssl_wrap_socket
    ssl_sock = _ssl_wrap_socket_impl(sock, context, tls_in_tls)
  File "C:\Users\PC\anaconda3\envs\howsam-deep\lib\site-packages\urllib3\util\ssl_.py", line 495, in _ssl_wrap_socket_impl
    return ssl_context.wrap_socket(sock)
  File "C:\Users\PC\anaconda3\envs\howsam-deep\lib\ssl.py", line 500, in wrap_socket
    return self.sslsocket_class._create(
  File "C:\Users\PC\anaconda3\envs\howsam-deep\lib\ssl.py", line 1040, in _create
    self.do_handshake()
  File "C:\Users\PC\anaconda3\envs\howsam-deep\lib\ssl.py", line 1309, in do_handshake
    self._sslobj.do_handshake()
ssl.SSLEOFError: EOF occurred in violation of protocol (_ssl.c:1129)

During handling of the above exception, another exception occurred:

Traceback (most recent call last):
  File "C:\Users\PC\anaconda3\envs\howsam-deep\lib\site-packages\requests\adapters.py", line 440, in send
    resp = conn.urlopen(
  File "C:\Users\PC\anaconda3\envs\howsam-deep\lib\site-packages\urllib3\connectionpool.py", line 787, in urlopen
    retries = retries.increment(
  File "C:\Users\PC\anaconda3\envs\howsam-deep\lib\site-packages\urllib3\util\retry.py", line 592, in increment
    raise MaxRetryError(_pool, url, error or ResponseError(cause))
urllib3.exceptions.MaxRetryError: HTTPSConnectionPool(host='api.wandb.ai', port=443): Max retries exceeded with url: /graphql (Caused by SSLError(SSLEOFError(8, 'EOF occurred in violation of protocol (_ssl.c:1129)')))

During handling of the above exception, another exception occurred:

Traceback (most recent call last):
  File "C:\Users\PC\anaconda3\envs\howsam-deep\lib\site-packages\wandb\sdk\lib\retry.py", line 113, in __call__
    result = self._call_fn(*args, **kwargs)
  File "C:\Users\PC\anaconda3\envs\howsam-deep\lib\site-packages\wandb\sdk\internal\internal_api.py", line 204, in execute
    return self.client.execute(*args, **kwargs)  # type: ignore
  File "C:\Users\PC\anaconda3\envs\howsam-deep\lib\site-packages\wandb\vendor\gql-0.2.0\wandb_gql\client.py", line 52, in execute
    result = self._get_result(document, *args, **kwargs)
  File "C:\Users\PC\anaconda3\envs\howsam-deep\lib\site-packages\wandb\vendor\gql-0.2.0\wandb_gql\client.py", line 60, in _get_result
    return self.transport.execute(document, *args, **kwargs)
  File "C:\Users\PC\anaconda3\envs\howsam-deep\lib\site-packages\wandb\vendor\gql-0.2.0\wandb_gql\transport\requests.py", line 38, in execute
    request = requests.post(self.url, **post_args)
  File "C:\Users\PC\anaconda3\envs\howsam-deep\lib\site-packages\requests\api.py", line 117, in post
    return request('post', url, data=data, json=json, **kwargs)
  File "C:\Users\PC\anaconda3\envs\howsam-deep\lib\site-packages\requests\api.py", line 61, in request
    return session.request(method=method, url=url, **kwargs)
  File "C:\Users\PC\anaconda3\envs\howsam-deep\lib\site-packages\requests\sessions.py", line 529, in request
    resp = self.send(prep, **send_kwargs)
  File "C:\Users\PC\anaconda3\envs\howsam-deep\lib\site-packages\requests\sessions.py", line 645, in send
    r = adapter.send(request, **kwargs)
  File "C:\Users\PC\anaconda3\envs\howsam-deep\lib\site-packages\requests\adapters.py", line 517, in send
    raise SSLError(e, request=request)
requests.exceptions.SSLError: HTTPSConnectionPool(host='api.wandb.ai', port=443): Max retries exceeded with url: /graphql (Caused by SSLError(SSLEOFError(8, 'EOF occurred in violation of protocol (_ssl.c:1129)')))
2023-09-21 14:28:32,747 INFO    MainThread:8384 [wandb_settings.py:_apply_login():1531] Applying login settings: {'api_key': '***REDACTED***'}
2023-09-21 14:28:32,747 INFO    MainThread:8384 [wandb_settings.py:_apply_login():1531] Applying login settings: {'api_key': '***REDACTED***'}
2023-09-21 14:28:36,074 ERROR   Thread-90 :8384 [retry.py:__call__():154] Retry attempt failed:
Traceback (most recent call last):
  File "C:\Users\PC\anaconda3\envs\howsam-deep\lib\site-packages\urllib3\connectionpool.py", line 700, in urlopen
    self._prepare_proxy(conn)
  File "C:\Users\PC\anaconda3\envs\howsam-deep\lib\site-packages\urllib3\connectionpool.py", line 996, in _prepare_proxy
    conn.connect()
  File "C:\Users\PC\anaconda3\envs\howsam-deep\lib\site-packages\urllib3\connection.py", line 364, in connect
    self.sock = conn = self._connect_tls_proxy(hostname, conn)
  File "C:\Users\PC\anaconda3\envs\howsam-deep\lib\site-packages\urllib3\connection.py", line 499, in _connect_tls_proxy
    socket = ssl_wrap_socket(
  File "C:\Users\PC\anaconda3\envs\howsam-deep\lib\site-packages\urllib3\util\ssl_.py", line 453, in ssl_wrap_socket
    ssl_sock = _ssl_wrap_socket_impl(sock, context, tls_in_tls)
  File "C:\Users\PC\anaconda3\envs\howsam-deep\lib\site-packages\urllib3\util\ssl_.py", line 495, in _ssl_wrap_socket_impl
    return ssl_context.wrap_socket(sock)
  File "C:\Users\PC\anaconda3\envs\howsam-deep\lib\ssl.py", line 500, in wrap_socket
    return self.sslsocket_class._create(
  File "C:\Users\PC\anaconda3\envs\howsam-deep\lib\ssl.py", line 1040, in _create
    self.do_handshake()
  File "C:\Users\PC\anaconda3\envs\howsam-deep\lib\ssl.py", line 1309, in do_handshake
    self._sslobj.do_handshake()
ssl.SSLEOFError: EOF occurred in violation of protocol (_ssl.c:1129)

During handling of the above exception, another exception occurred:

Traceback (most recent call last):
  File "C:\Users\PC\anaconda3\envs\howsam-deep\lib\site-packages\requests\adapters.py", line 440, in send
    resp = conn.urlopen(
  File "C:\Users\PC\anaconda3\envs\howsam-deep\lib\site-packages\urllib3\connectionpool.py", line 787, in urlopen
    retries = retries.increment(
  File "C:\Users\PC\anaconda3\envs\howsam-deep\lib\site-packages\urllib3\util\retry.py", line 592, in increment
    raise MaxRetryError(_pool, url, error or ResponseError(cause))
urllib3.exceptions.MaxRetryError: HTTPSConnectionPool(host='api.wandb.ai', port=443): Max retries exceeded with url: /graphql (Caused by SSLError(SSLEOFError(8, 'EOF occurred in violation of protocol (_ssl.c:1129)')))

During handling of the above exception, another exception occurred:

Traceback (most recent call last):
  File "C:\Users\PC\anaconda3\envs\howsam-deep\lib\site-packages\wandb\sdk\lib\retry.py", line 113, in __call__
    result = self._call_fn(*args, **kwargs)
  File "C:\Users\PC\anaconda3\envs\howsam-deep\lib\site-packages\wandb\sdk\internal\internal_api.py", line 204, in execute
    return self.client.execute(*args, **kwargs)  # type: ignore
  File "C:\Users\PC\anaconda3\envs\howsam-deep\lib\site-packages\wandb\vendor\gql-0.2.0\wandb_gql\client.py", line 52, in execute
    result = self._get_result(document, *args, **kwargs)
  File "C:\Users\PC\anaconda3\envs\howsam-deep\lib\site-packages\wandb\vendor\gql-0.2.0\wandb_gql\client.py", line 60, in _get_result
    return self.transport.execute(document, *args, **kwargs)
  File "C:\Users\PC\anaconda3\envs\howsam-deep\lib\site-packages\wandb\vendor\gql-0.2.0\wandb_gql\transport\requests.py", line 38, in execute
    request = requests.post(self.url, **post_args)
  File "C:\Users\PC\anaconda3\envs\howsam-deep\lib\site-packages\requests\api.py", line 117, in post
    return request('post', url, data=data, json=json, **kwargs)
  File "C:\Users\PC\anaconda3\envs\howsam-deep\lib\site-packages\requests\api.py", line 61, in request
    return session.request(method=method, url=url, **kwargs)
  File "C:\Users\PC\anaconda3\envs\howsam-deep\lib\site-packages\requests\sessions.py", line 529, in request
    resp = self.send(prep, **send_kwargs)
  File "C:\Users\PC\anaconda3\envs\howsam-deep\lib\site-packages\requests\sessions.py", line 645, in send
    r = adapter.send(request, **kwargs)
  File "C:\Users\PC\anaconda3\envs\howsam-deep\lib\site-packages\requests\adapters.py", line 517, in send
    raise SSLError(e, request=request)
requests.exceptions.SSLError: HTTPSConnectionPool(host='api.wandb.ai', port=443): Max retries exceeded with url: /graphql (Caused by SSLError(SSLEOFError(8, 'EOF occurred in violation of protocol (_ssl.c:1129)')))
2023-09-21 14:28:55,759 INFO    MainThread:8384 [wandb_settings.py:_apply_login():1531] Applying login settings: {'api_key': '***REDACTED***'}
2023-09-21 14:28:55,759 INFO    MainThread:8384 [wandb_settings.py:_apply_login():1531] Applying login settings: {'api_key': '***REDACTED***'}
2023-09-21 14:28:59,301 ERROR   Thread-105:8384 [retry.py:__call__():154] Retry attempt failed:
Traceback (most recent call last):
  File "C:\Users\PC\anaconda3\envs\howsam-deep\lib\site-packages\urllib3\connectionpool.py", line 700, in urlopen
    self._prepare_proxy(conn)
  File "C:\Users\PC\anaconda3\envs\howsam-deep\lib\site-packages\urllib3\connectionpool.py", line 996, in _prepare_proxy
    conn.connect()
  File "C:\Users\PC\anaconda3\envs\howsam-deep\lib\site-packages\urllib3\connection.py", line 364, in connect
    self.sock = conn = self._connect_tls_proxy(hostname, conn)
  File "C:\Users\PC\anaconda3\envs\howsam-deep\lib\site-packages\urllib3\connection.py", line 499, in _connect_tls_proxy
    socket = ssl_wrap_socket(
  File "C:\Users\PC\anaconda3\envs\howsam-deep\lib\site-packages\urllib3\util\ssl_.py", line 453, in ssl_wrap_socket
    ssl_sock = _ssl_wrap_socket_impl(sock, context, tls_in_tls)
  File "C:\Users\PC\anaconda3\envs\howsam-deep\lib\site-packages\urllib3\util\ssl_.py", line 495, in _ssl_wrap_socket_impl
    return ssl_context.wrap_socket(sock)
  File "C:\Users\PC\anaconda3\envs\howsam-deep\lib\ssl.py", line 500, in wrap_socket
    return self.sslsocket_class._create(
  File "C:\Users\PC\anaconda3\envs\howsam-deep\lib\ssl.py", line 1040, in _create
    self.do_handshake()
  File "C:\Users\PC\anaconda3\envs\howsam-deep\lib\ssl.py", line 1309, in do_handshake
    self._sslobj.do_handshake()
ssl.SSLEOFError: EOF occurred in violation of protocol (_ssl.c:1129)

During handling of the above exception, another exception occurred:

Traceback (most recent call last):
  File "C:\Users\PC\anaconda3\envs\howsam-deep\lib\site-packages\requests\adapters.py", line 440, in send
    resp = conn.urlopen(
  File "C:\Users\PC\anaconda3\envs\howsam-deep\lib\site-packages\urllib3\connectionpool.py", line 787, in urlopen
    retries = retries.increment(
  File "C:\Users\PC\anaconda3\envs\howsam-deep\lib\site-packages\urllib3\util\retry.py", line 592, in increment
    raise MaxRetryError(_pool, url, error or ResponseError(cause))
urllib3.exceptions.MaxRetryError: HTTPSConnectionPool(host='api.wandb.ai', port=443): Max retries exceeded with url: /graphql (Caused by SSLError(SSLEOFError(8, 'EOF occurred in violation of protocol (_ssl.c:1129)')))

During handling of the above exception, another exception occurred:

Traceback (most recent call last):
  File "C:\Users\PC\anaconda3\envs\howsam-deep\lib\site-packages\wandb\sdk\lib\retry.py", line 113, in __call__
    result = self._call_fn(*args, **kwargs)
  File "C:\Users\PC\anaconda3\envs\howsam-deep\lib\site-packages\wandb\sdk\internal\internal_api.py", line 204, in execute
    return self.client.execute(*args, **kwargs)  # type: ignore
  File "C:\Users\PC\anaconda3\envs\howsam-deep\lib\site-packages\wandb\vendor\gql-0.2.0\wandb_gql\client.py", line 52, in execute
    result = self._get_result(document, *args, **kwargs)
  File "C:\Users\PC\anaconda3\envs\howsam-deep\lib\site-packages\wandb\vendor\gql-0.2.0\wandb_gql\client.py", line 60, in _get_result
    return self.transport.execute(document, *args, **kwargs)
  File "C:\Users\PC\anaconda3\envs\howsam-deep\lib\site-packages\wandb\vendor\gql-0.2.0\wandb_gql\transport\requests.py", line 38, in execute
    request = requests.post(self.url, **post_args)
  File "C:\Users\PC\anaconda3\envs\howsam-deep\lib\site-packages\requests\api.py", line 117, in post
    return request('post', url, data=data, json=json, **kwargs)
  File "C:\Users\PC\anaconda3\envs\howsam-deep\lib\site-packages\requests\api.py", line 61, in request
    return session.request(method=method, url=url, **kwargs)
  File "C:\Users\PC\anaconda3\envs\howsam-deep\lib\site-packages\requests\sessions.py", line 529, in request
    resp = self.send(prep, **send_kwargs)
  File "C:\Users\PC\anaconda3\envs\howsam-deep\lib\site-packages\requests\sessions.py", line 645, in send
    r = adapter.send(request, **kwargs)
  File "C:\Users\PC\anaconda3\envs\howsam-deep\lib\site-packages\requests\adapters.py", line 517, in send
    raise SSLError(e, request=request)
requests.exceptions.SSLError: HTTPSConnectionPool(host='api.wandb.ai', port=443): Max retries exceeded with url: /graphql (Caused by SSLError(SSLEOFError(8, 'EOF occurred in violation of protocol (_ssl.c:1129)')))
2023-09-21 14:29:11,672 INFO    MainThread:8384 [wandb_setup.py:_flush():76] Configure stats pid to 8384
2023-09-21 14:29:11,672 INFO    MainThread:8384 [wandb_setup.py:_flush():76] Loading settings from C:\Users\PC\.config\wandb\settings
2023-09-21 14:29:11,672 INFO    MainThread:8384 [wandb_setup.py:_flush():76] Loading settings from D:\Howsam\Deep Catalyst\project 1 language modeling\code\howsam\wandb\settings
2023-09-21 14:29:11,672 INFO    MainThread:8384 [wandb_setup.py:_flush():76] Loading settings from environment variables: {'_require_service': 'True'}
2023-09-21 14:29:11,672 INFO    MainThread:8384 [wandb_setup.py:_flush():76] Inferring run settings from compute environment: {'program_relpath': 'main.py', 'program': 'D:/Howsam/Deep Catalyst/project 1 language modeling/code/howsam/main.py'}
2023-09-21 14:29:11,672 INFO    MainThread:8384 [wandb_setup.py:_flush():76] Applying login settings: {'api_key': '***REDACTED***'}
2023-09-21 14:29:11,672 INFO    MainThread:8384 [wandb_setup.py:_flush():76] Applying login settings: {'api_key': '***REDACTED***'}
2023-09-21 14:29:11,672 INFO    MainThread:8384 [wandb_init.py:_log_setup():461] Logging user logs to D:\Howsam\Deep Catalyst\project 1 language modeling\code\howsam\wandb\run-20230921_142911-1722phgx\logs\debug.log
2023-09-21 14:29:11,672 INFO    MainThread:8384 [wandb_init.py:_log_setup():462] Logging internal logs to D:\Howsam\Deep Catalyst\project 1 language modeling\code\howsam\wandb\run-20230921_142911-1722phgx\logs\debug-internal.log
2023-09-21 14:29:11,672 INFO    MainThread:8384 [wandb_init.py:_jupyter_setup():411] configuring jupyter hooks <wandb.sdk.wandb_init._WandbInit object at 0x000002A51CAD06D0>
2023-09-21 14:29:11,672 INFO    MainThread:8384 [wandb_init.py:init():495] calling init triggers
2023-09-21 14:29:11,672 INFO    MainThread:8384 [wandb_init.py:init():498] wandb.init called with sweep_config: {}
config: {'learning_rate': 0.5, 'epochs': 31}
2023-09-21 14:29:11,672 INFO    MainThread:8384 [wandb_init.py:init():548] starting backend
2023-09-21 14:29:11,672 INFO    MainThread:8384 [wandb_init.py:init():552] setting up manager
2023-09-21 14:29:11,704 ERROR   MainThread:8384 [wandb_init.py:init():1070] error
Traceback (most recent call last):
  File "C:\Users\PC\anaconda3\envs\howsam-deep\lib\site-packages\wandb\sdk\wandb_init.py", line 1043, in init
    run = wi.init()
  File "C:\Users\PC\anaconda3\envs\howsam-deep\lib\site-packages\wandb\sdk\wandb_init.py", line 553, in init
    manager._inform_init(settings=self.settings, run_id=self.settings.run_id)
  File "C:\Users\PC\anaconda3\envs\howsam-deep\lib\site-packages\wandb\sdk\wandb_manager.py", line 161, in _inform_init
    svc_iface._svc_inform_init(settings=settings, run_id=run_id)
  File "C:\Users\PC\anaconda3\envs\howsam-deep\lib\site-packages\wandb\sdk\service\service_sock.py", line 39, in _svc_inform_init
    self._sock_client.send(inform_init=inform_init)
  File "C:\Users\PC\anaconda3\envs\howsam-deep\lib\site-packages\wandb\sdk\lib\sock_client.py", line 140, in send
    self.send_server_request(server_req)
  File "C:\Users\PC\anaconda3\envs\howsam-deep\lib\site-packages\wandb\sdk\lib\sock_client.py", line 84, in send_server_request
    self._send_message(msg)
  File "C:\Users\PC\anaconda3\envs\howsam-deep\lib\site-packages\wandb\sdk\lib\sock_client.py", line 81, in _send_message
    self._sendall_with_error_handle(header + data)
  File "C:\Users\PC\anaconda3\envs\howsam-deep\lib\site-packages\wandb\sdk\lib\sock_client.py", line 61, in _sendall_with_error_handle
    sent = self._sock.send(data[total_sent:])
ConnectionResetError: [WinError 10054] An existing connection was forcibly closed by the remote host
