2023-09-21 15:08:01,922 INFO    StreamThr :13492 [internal.py:wandb_internal():90] W&B internal server running at pid: 13492, started at: 2023-09-21 15:08:01.922157
2023-09-21 15:08:01,922 DEBUG   HandlerThread:13492 [handler.py:handle_request():141] handle_request: status
2023-09-21 15:08:01,937 DEBUG   SenderThread:13492 [sender.py:send_request():316] send_request: status
2023-09-21 15:08:01,937 DEBUG   SenderThread:13492 [sender.py:send():302] send: header
2023-09-21 15:08:01,937 INFO    WriterThread:13492 [datastore.py:open_for_write():75] open: D:\Howsam\Deep Catalyst\project 1 language modeling\code\howsam\wandb\run-20230921_150801-g6hxo3h3\run-g6hxo3h3.wandb
2023-09-21 15:08:01,937 DEBUG   SenderThread:13492 [sender.py:send():302] send: run
2023-09-21 15:08:05,324 ERROR   SenderThread:13492 [retry.py:__call__():154] Retry attempt failed:
Traceback (most recent call last):
  File "C:\Users\PC\anaconda3\envs\howsam-deep\lib\site-packages\urllib3\connectionpool.py", line 700, in urlopen
    self._prepare_proxy(conn)
  File "C:\Users\PC\anaconda3\envs\howsam-deep\lib\site-packages\urllib3\connectionpool.py", line 996, in _prepare_proxy
    conn.connect()
  File "C:\Users\PC\anaconda3\envs\howsam-deep\lib\site-packages\urllib3\connection.py", line 364, in connect
    self.sock = conn = self._connect_tls_proxy(hostname, conn)
  File "C:\Users\PC\anaconda3\envs\howsam-deep\lib\site-packages\urllib3\connection.py", line 499, in _connect_tls_proxy
    socket = ssl_wrap_socket(
  File "C:\Users\PC\anaconda3\envs\howsam-deep\lib\site-packages\urllib3\util\ssl_.py", line 453, in ssl_wrap_socket
    ssl_sock = _ssl_wrap_socket_impl(sock, context, tls_in_tls)
  File "C:\Users\PC\anaconda3\envs\howsam-deep\lib\site-packages\urllib3\util\ssl_.py", line 495, in _ssl_wrap_socket_impl
    return ssl_context.wrap_socket(sock)
  File "C:\Users\PC\anaconda3\envs\howsam-deep\lib\ssl.py", line 500, in wrap_socket
    return self.sslsocket_class._create(
  File "C:\Users\PC\anaconda3\envs\howsam-deep\lib\ssl.py", line 1040, in _create
    self.do_handshake()
  File "C:\Users\PC\anaconda3\envs\howsam-deep\lib\ssl.py", line 1309, in do_handshake
    self._sslobj.do_handshake()
ssl.SSLEOFError: EOF occurred in violation of protocol (_ssl.c:1129)

During handling of the above exception, another exception occurred:

Traceback (most recent call last):
  File "C:\Users\PC\anaconda3\envs\howsam-deep\lib\site-packages\requests\adapters.py", line 440, in send
    resp = conn.urlopen(
  File "C:\Users\PC\anaconda3\envs\howsam-deep\lib\site-packages\urllib3\connectionpool.py", line 787, in urlopen
    retries = retries.increment(
  File "C:\Users\PC\anaconda3\envs\howsam-deep\lib\site-packages\urllib3\util\retry.py", line 592, in increment
    raise MaxRetryError(_pool, url, error or ResponseError(cause))
urllib3.exceptions.MaxRetryError: HTTPSConnectionPool(host='api.wandb.ai', port=443): Max retries exceeded with url: /graphql (Caused by SSLError(SSLEOFError(8, 'EOF occurred in violation of protocol (_ssl.c:1129)')))

During handling of the above exception, another exception occurred:

Traceback (most recent call last):
  File "C:\Users\PC\anaconda3\envs\howsam-deep\lib\site-packages\wandb\sdk\lib\retry.py", line 113, in __call__
    result = self._call_fn(*args, **kwargs)
  File "C:\Users\PC\anaconda3\envs\howsam-deep\lib\site-packages\wandb\sdk\internal\internal_api.py", line 204, in execute
    return self.client.execute(*args, **kwargs)  # type: ignore
  File "C:\Users\PC\anaconda3\envs\howsam-deep\lib\site-packages\wandb\vendor\gql-0.2.0\wandb_gql\client.py", line 52, in execute
    result = self._get_result(document, *args, **kwargs)
  File "C:\Users\PC\anaconda3\envs\howsam-deep\lib\site-packages\wandb\vendor\gql-0.2.0\wandb_gql\client.py", line 60, in _get_result
    return self.transport.execute(document, *args, **kwargs)
  File "C:\Users\PC\anaconda3\envs\howsam-deep\lib\site-packages\wandb\vendor\gql-0.2.0\wandb_gql\transport\requests.py", line 38, in execute
    request = requests.post(self.url, **post_args)
  File "C:\Users\PC\anaconda3\envs\howsam-deep\lib\site-packages\requests\api.py", line 117, in post
    return request('post', url, data=data, json=json, **kwargs)
  File "C:\Users\PC\anaconda3\envs\howsam-deep\lib\site-packages\requests\api.py", line 61, in request
    return session.request(method=method, url=url, **kwargs)
  File "C:\Users\PC\anaconda3\envs\howsam-deep\lib\site-packages\requests\sessions.py", line 529, in request
    resp = self.send(prep, **send_kwargs)
  File "C:\Users\PC\anaconda3\envs\howsam-deep\lib\site-packages\requests\sessions.py", line 645, in send
    r = adapter.send(request, **kwargs)
  File "C:\Users\PC\anaconda3\envs\howsam-deep\lib\site-packages\requests\adapters.py", line 517, in send
    raise SSLError(e, request=request)
requests.exceptions.SSLError: HTTPSConnectionPool(host='api.wandb.ai', port=443): Max retries exceeded with url: /graphql (Caused by SSLError(SSLEOFError(8, 'EOF occurred in violation of protocol (_ssl.c:1129)')))
2023-09-21 15:08:31,935 DEBUG   HandlerThread:13492 [handler.py:handle_request():141] handle_request: poll_exit
